<mujoco model="bittle">
  <option iterations="1000" timestep="0.0005" solver="Newton" gravity="0 0 -9.81" cone="elliptic"  />

  <compiler angle="radian" meshdir="assets" eulerseq="zyx" autolimits="true" />

  <default>
    <joint limited="true" damping="0.01" armature="0.01" frictionloss="0.1" />
    <geom condim="3" contype="1" conaffinity="1" friction=".9 .2 .2" solref="0.001 2.75" solimp="0.9 .95 0.1" />
    <motor ctrllimited="false" />
    <equality solref="0.01 1.1" />
    <default class="visualgeom">
      <geom material="visualgeom" condim="1" contype="1" conaffinity="15" />
    </default>
  </default>

  <asset>
    <mesh name="base_frame.001" file="assets/base_frame.001.obj" />
    <mesh name="battery.001" file="assets/battery.001.obj" />
    <mesh name="cover.001" file="assets/cover.001.obj" />
    <mesh name="left_knee.002" file="assets/left_knee.002.obj" />
    <mesh name="shoulder.004" file="assets/shoulder.004.obj" />
    <mesh name="left_knee.003" file="assets/left_knee.003.obj" />
    <mesh name="shoulder.007" file="assets/shoulder.007.obj" />
    <mesh name="right_knee.002" file="assets/right_knee.002.obj" />
    <mesh name="shoulder.005" file="assets/shoulder.005.obj" />
    <mesh name="right_knee.003" file="assets/right_knee.003.obj" />
    <mesh name="shoulder.006" file="assets/shoulder.006.obj" />
    <texture name="texplane" type="2d" builtin="checker" rgb1=".99 .41 .12" rgb2=".099 .41 .12" width="100" height="100" />
    <material name="matplane" reflectance="0." texture="texplane" texrepeat="1 1" texuniform="true" />
    <material name="visualgeom" rgba="0.5 0.9 0.2 1" />
  </asset>

  <worldbody>
    <light directional="true" diffuse="0.4 0.4 0.4" specular="0.1 0.1 0.1" pos="0 0 5.0" dir="0 0 -1" castshadow="false" />
    <light directional="true" diffuse="0.6 0.6 0.6" specular="0.2 0.2 0.2" pos="0 0 4" dir="0 0 -1" />
    <geom name="ground"  type="plane" pos="0 0 0" size="100 100 0.001" quat="1 0 0 0" material="matplane" condim="6" conaffinity="15" />
    <camera name="fixed" pos="0 -3.0 1.4239305602569667" xyaxes="1 0 0 0 0 1" />
    <camera name="track" mode="trackcom" pos="0 -3.0 1.4239305602569667" xyaxes="1 0 0 0 0 1" />
    <body name="root" pos="0 0 0.9239305602569667" quat="1 0 0 0">
      <freejoint name="root" />
      <site name="imu" size="0.01" pos="0 0 0" />
      <site name="head" pos=".1 0 0.1" size="0.01"/>
      <inertial pos="0 -0.04 -0.02" mass="0.165" diaginertia="0.001 0.001 0.001" />
      <geom name="base_frame_c" type="mesh" mesh="base_frame.001" contype="1" conaffinity="15"  group="1" class="visualgeom" />
      <geom type="mesh" rgba="0.0 0.0 0.8 1" mesh="base_frame.001" />
      <geom name="battery_c" pos="0.00047 -0.00917 -0.04848" quat="1 0 0 0" type="mesh" mesh="battery.001" contype="1" conaffinity="15" group="1" class="visualgeom" />
      <geom type="mesh" rgba="" mesh="battery.001" pos="0.00047 -0.00917 -0.04848" quat="1 0 0 0" />
      <geom name="cover_c" pos="0.0014 0 0.1251" quat="1 0 0 0" type="mesh" mesh="cover.001" contype="1" conaffinity="15"  group="1" class="visualgeom" />
      <geom type="mesh" rgba="0.0 0.0 0.8 1" mesh="cover.001" pos="0.0014 0 0.1251" quat="1 0 0 0" />
      <body name="left-back-shoulder-link" pos="-0.44596 -0.51923 -0.02102" quat="0.499998 0.5 -0.500002 -0.5">
        <inertial pos="0 -0.24575 0.04372" quat="0.707107 0.707107 0 0" mass="0.006" diaginertia="0.00044 0.00044 2e-05" />
        <joint name="left-back-shoulder-joint" pos="0 0 0" axis="0 0 1" range="-1.5708 1.6" actuatorfrcrange="-1000 1000" />
        <geom name="left_back_shoulder_c" pos="0 -0.24575 0.04372" quat="0.499998 -0.5 0.5 0.500002" type="mesh" mesh="shoulder.004" contype="1" conaffinity="15"  group="1" class="visualgeom" />
        <geom type="mesh" rgba="0.0 0.0 0.8 1" mesh="shoulder.004" pos="0 -0.24575 0.04372" quat="0.499998 -0.5 0.5 0.500002" />
        <body name="left-back-knee-link" pos="0 -0.49172 0">
          <inertial pos="-0.08998 0 -0.14638" quat="0.385725 0.189855 0.608868 0.666671" mass="0.017" diaginertia="0.000836537 0.000627558 0.000415905" />
          <joint name="left-back-knee-joint" pos="0 0 0" axis="0 0 1" range="-1.22173 1.48353" actuatorfrcrange="-1000 1000" />
          <geom name="left_back_knee_c" pos="-0.08998 0 -0.14638" quat="0.499998 -0.5 0.5 0.500002" type="mesh" mesh="left_knee.002" contype="1" conaffinity="15"  group="1" class="visualgeom" />
          <geom type="mesh" rgba="0.0 0.0 0.8 1" mesh="left_knee.002" pos="-0.08998 0 -0.14638" quat="0.499998 -0.5 0.5 0.500002" />
          <site name="LB_foot" pos="0 0 -0.15" size="0.015"/>
        </body>
      </body>
      <body name="left-front-shoulder-link" pos="-0.44596 0.52264 -0.02102" quat="0.499998 0.5 -0.500002 -0.5">
        <inertial pos="0 -0.24575 0.04372" quat="0.707107 0.707107 0 0" mass="0.006" diaginertia="0.00044 0.00044 2e-05" />
        <joint name="left-front-shoulder-joint" pos="0 0 0" axis="0 0 1" range="-1.5708 2.6" actuatorfrcrange="-1000 1000" />
        <geom name="left_front_shoulder_c" pos="0 -0.24575 0.04372" quat="0.499998 -0.5 0.5 0.500002" type="mesh" mesh="shoulder.007" contype="1" conaffinity="15"  group="1" class="visualgeom" />
        <geom type="mesh" rgba="0.0 0.0 0.8 1" mesh="shoulder.007" pos="0 -0.24575 0.04372" quat="0.499998 -0.5 0.5 0.500002" />
        <body name="left-front-knee-link" pos="6e-05 -0.49172 0">
          <inertial pos="-0.09232 0 -0.14614" quat="0.648853 -0.0696517 0.415405 0.633701" mass="0.017" diaginertia="0.000703116 0.000604252 0.000572632" />
          <joint name="left-front-knee-joint" pos="0 0 0" axis="0 0 1" range="-1.22173 1.48353" actuatorfrcrange="-1000 1000" />
          <geom name="left_front_knee_c" pos="-0.09232 0 -0.14614" quat="0.499998 -0.5 0.5 0.500002" type="mesh" mesh="left_knee.003" contype="1" conaffinity="15"  group="1" class="visualgeom" />
          <geom type="mesh" rgba="0.0 0.0 0.8 1" mesh="left_knee.003" pos="-0.09232 0 -0.14614" quat="0.499998 -0.5 0.5 0.500002" />
          <site name="LF_foot" pos="0 0 -0.15" size="0.015"/>
        </body>
      </body>
      <body name="right-back-shoulder-link" pos="0.45149 -0.51923 -0.02102" quat="0.499998 -0.5 0.500002 -0.5">
        <inertial pos="0 0.24575 0.0777" quat="0.707107 0.707107 0 0" mass="0.006" diaginertia="0.00044 0.00044 2e-05" />
        <joint name="right-back-shoulder-joint" pos="0 0 0" axis="0 0 -1" range="-1.5708 1.6" actuatorfrcrange="-1000 1000" />
        <geom name="right_back_shoulder_c" pos="0 0.24575 0.0777" quat="0.499998 0.5 -0.5 0.500002" type="mesh" mesh="shoulder.005" contype="1" conaffinity="15"  group="1" class="visualgeom" />
        <geom type="mesh" rgba="0.0 0.0 0.8 1" mesh="shoulder.005" pos="0 0.24575 0.0777" quat="0.499998 0.5 -0.5 0.500002" />
        <body name="right-back-knee-link" pos="0.00015 0.49938 0.03996" quat="1.32679e-06 0 0 1">
          <inertial pos="0.08426 -0.00238 -0.1382" quat="0.64714 0.175903 0.606664 0.42688" mass="0.017" diaginertia="0.000676185 0.000616918 0.000596897" />
          <joint name="right-back-knee-joint" pos="0 0 0" axis="0 0 -1" range="-1.22173 1.48353" actuatorfrcrange="-1000 1000" />
          <geom name="right_back_knee_c" pos="0.08426 -0.00238 -0.1382" quat="0.499998 -0.5 -0.5 -0.500002" type="mesh" mesh="right_knee.002" contype="1" conaffinity="15"  group="1" class="visualgeom" />
          <geom type="mesh" rgba="0.0 0.0 0.8 1" mesh="right_knee.002" pos="0.08426 -0.00238 -0.1382" quat="0.499998 -0.5 -0.5 -0.500002" />
          <site name="RB_foot" pos="0 0 -0.15" size="0.015"/>
        </body>
      </body>
      <body name="right-front-shoulder-link" pos="0.45149 0.52264 -0.02102" quat="0.499998 -0.5 0.500002 -0.5">
        <inertial pos="0 0.24575 0.0777" quat="0.707107 0.707107 0 0" mass="0.006" diaginertia="0.00044 0.00044 2e-05" />
        <joint name="right-front-shoulder-joint" pos="0 0 0" axis="0 0 -1" range="-1.5708 2.6" actuatorfrcrange="-1000 1000" />
        <geom name="right_front_shoulder_c" pos="0 0.24575 0.0777" quat="0.499998 0.5 -0.5 0.500002" type="mesh" mesh="shoulder.006" contype="1" conaffinity="15"  group="1" class="visualgeom" />
        <geom type="mesh" rgba="0.0 0.0 0.8 1" mesh="shoulder.006" pos="0 0.24575 0.0777" quat="0.499998 0.5 -0.5 0.500002" />
        <body name="right-front-knee-link" pos="6e-05 0.49938 0.03996" quat="1.32679e-06 0 0 1">
          <inertial pos="0.09497 -0.00238 -0.1382" quat="0.64714 0.175903 0.606664 0.42688" mass="0.017" diaginertia="0.000676185 0.000616918 0.000596897" />
          <joint name="right-front-knee-joint" pos="0 0 0" axis="0 0 -1" range="-1.22173 1.48353" actuatorfrcrange="-1000 1000" />
         <geom name="right_front_knee_c" pos="0.09497 -0.00238 -0.1382" quat="0.499998 -0.5 -0.5 -0.500002" type="mesh" mesh="right_knee.003" contype="1" conaffinity="15"  group="1" class="visualgeom" />
          <geom type="mesh" rgba="0.0 0.0 0.8 1" mesh="right_knee.003" pos="0.09497 -0.00238 -0.1382" quat="0.499998 -0.5 -0.5 -0.500002" />
          <site name="RF_foot" pos="0 0 -0.15" size="0.015"/>
        </body>
      </body>
    </body>
  </worldbody>

  <actuator>
    <position name="left-front-shoulder-joint" joint="left-front-shoulder-joint"   ctrllimited="true"  ctrlrange="-10 10" gear="1" forcelimited="true"   forcerange="-1.75 1.75"/>
    <position name="left-front-knee-joint" joint="left-front-knee-joint"           ctrllimited="true"  ctrlrange="-10 10" gear="1" forcelimited="true"   forcerange="-1.75 1.75"/>
    <position name="left-back-shoulder-joint" joint="left-back-shoulder-joint"     ctrllimited="true"  ctrlrange="-10 10" gear="1" forcelimited="true"   forcerange="-1.75 1.75"/>
    <position name="left-back-knee-joint" joint="left-back-knee-joint"             ctrllimited="true"  ctrlrange="-10 10" gear="1" forcelimited="true"   forcerange="-1.75 1.75"/>
    <position name="right-back-shoulder-joint" joint="right-back-shoulder-joint"   ctrllimited="true"  ctrlrange="-10 10" gear="1" forcelimited="true"   forcerange="-1.75 1.75"/>
    <position name="right-back-knee-joint" joint="right-back-knee-joint"           ctrllimited="true"  ctrlrange="-10 10" gear="1" forcelimited="true"   forcerange="-1.75 1.75"/>
    <position name="right-front-shoulder-joint" joint="right-front-shoulder-joint" ctrllimited="true"  ctrlrange="-10 10" gear="1" forcelimited="true"   forcerange="-1.75 1.75"/>
    <position name="right-front-knee-joint" joint="right-front-knee-joint"         ctrllimited="true"  ctrlrange="-10 10" gear="1" forcelimited="true"   forcerange="-1.75 1.75"/>
  </actuator>

  <sensor>
    <actuatorpos name="left-front-shoulder-joint_p" actuator="left-front-shoulder-joint" />
    <actuatorvel name="left-front-shoulder-joint_v" actuator="left-front-shoulder-joint" />
    <actuatorfrc name="left-front-shoulder-joint_f" actuator="left-front-shoulder-joint" noise="0.001" />
    <actuatorpos name="left-front-knee-joint_p" actuator="left-front-knee-joint" />
    <actuatorvel name="left-front-knee-joint_v" actuator="left-front-knee-joint" />
    <actuatorfrc name="left-front-knee-joint_f" actuator="left-front-knee-joint" noise="0.001" />
    <actuatorpos name="left-back-shoulder-joint_p" actuator="left-back-shoulder-joint" />
    <actuatorvel name="left-back-shoulder-joint_v" actuator="left-back-shoulder-joint" />
    <actuatorfrc name="left-back-shoulder-joint_f" actuator="left-back-shoulder-joint" noise="0.001" />
    <actuatorpos name="left-back-knee-joint_p" actuator="left-back-knee-joint" />
    <actuatorvel name="left-back-knee-joint_v" actuator="left-back-knee-joint" />
    <actuatorfrc name="left-back-knee-joint_f" actuator="left-back-knee-joint" noise="0.001" />
    <actuatorpos name="right-back-shoulder-joint_p" actuator="right-back-shoulder-joint" />
    <actuatorvel name="right-back-shoulder-joint_v" actuator="right-back-shoulder-joint" />
    <actuatorfrc name="right-back-shoulder-joint_f" actuator="right-back-shoulder-joint" noise="0.001" />
    <actuatorpos name="right-back-knee-joint_p" actuator="right-back-knee-joint" />
    <actuatorvel name="right-back-knee-joint_v" actuator="right-back-knee-joint" />
    <actuatorfrc name="right-back-knee-joint_f" actuator="right-back-knee-joint" noise="0.001" />
    <actuatorpos name="right-front-shoulder-joint_p" actuator="right-front-shoulder-joint" />
    <actuatorvel name="right-front-shoulder-joint_v" actuator="right-front-shoulder-joint" />
    <actuatorfrc name="right-front-shoulder-joint_f" actuator="right-front-shoulder-joint" noise="0.001" />
    <actuatorpos name="right-front-knee-joint_p" actuator="right-front-knee-joint" />
    <actuatorvel name="right-front-knee-joint_v" actuator="right-front-knee-joint" />
    <actuatorfrc name="right-front-knee-joint_f" actuator="right-front-knee-joint" noise="0.001" />
    <framequat name="orientation" objtype="site" noise="0.001" objname="imu" />
    <gyro name="angular-velocity" site="imu" noise="0.005" cutoff="34.9" />
  </sensor>
</mujoco>